<?xml version='1.0' encoding='utf-8'?>
<robot name="object">
  <link name="base">
    <inertial>
      <origin xyz="0 0 0" rpy="0 0 0" />
      <mass value="0.0" />
      <inertia ixx="0" ixy="0" ixz="0" iyy="0" iyz="0" izz="0" />
    </inertial>
  </link>
  <link name="link_1">
    <visual>
      <origin xyz="0 0 0" rpy="0 0 0" />
      <geometry>
        <mesh filename="meshes/link_1.stl" />
      </geometry>
    </visual>
    <collision>
      <origin xyz="0 0 0" rpy="0 0 0" />
      <geometry>
        <mesh filename="meshes/link_1.stl" />
      </geometry>
    </collision>
    <inertial>
      <origin xyz="0.551188201 0.002321258 -0.597484913" rpy="0 0 0" />
      <mass value="5.39384631" />
      <inertia ixx="0.0555192579" ixy="-1.26829041e-05" ixz="-0.00159988871" iyy="0.0598771754" iyz="2.37340164e-06" izz="0.113624958" />
    </inertial>
  </link>
  <link name="link_2">
    <visual>
      <origin xyz="-0.687455089 -0.00273809246 0.506032737" rpy="0 0 0" />
      <geometry>
        <mesh filename="meshes/link_2.stl" />
      </geometry>
    </visual>
    <collision>
      <origin xyz="-0.687455089 -0.00273809246 0.506032737" rpy="0 0 0" />
      <geometry>
        <mesh filename="meshes/link_2.stl" />
      </geometry>
    </collision>
    <inertial>
      <origin xyz="-0.317421354 -0.00121286351 0.499818052" rpy="0 0 0" />
      <mass value="2.09478233" />
      <inertia ixx="0.142182464" ixy="-3.44598275e-06" ixz="0.0450338722" iyy="0.152586606" iyz="7.98039411e-05" izz="0.0107310244" />
    </inertial>
  </link>
  <link name="link_3">
    <visual>
      <origin xyz="-0.29217409 -0.00236580938 -0.484597394" rpy="0 0 0" />
      <geometry>
        <mesh filename="meshes/link_3.stl" />
      </geometry>
    </visual>
    <collision>
      <origin xyz="-0.29217409 -0.00236580938 -0.484597394" rpy="0 0 0" />
      <geometry>
        <mesh filename="meshes/link_3.stl" />
      </geometry>
    </collision>
    <inertial>
      <origin xyz="-0.625867809 -0.00311677593 -0.671368681" rpy="0 0 0" />
      <mass value="-3.00913675" />
      <inertia ixx="1.40208738" ixy="-0.00174371466" ixz="-0.520816406" iyy="1.67694134" iyz="-0.00557886743" izz="0.275087064" />
    </inertial>
  </link>
  <link name="link_4">
    <visual>
      <origin xyz="0.602762058 0.00206676852 -0.578745101" rpy="0 0 0" />
      <geometry>
        <mesh filename="meshes/link_4.stl" />
      </geometry>
    </visual>
    <collision>
      <origin xyz="0.602762058 0.00206676852 -0.578745101" rpy="0 0 0" />
      <geometry>
        <mesh filename="meshes/link_4.stl" />
      </geometry>
    </collision>
    <inertial>
      <origin xyz="-0.141783705 -0.000914955643 -0.0972718163" rpy="0 0 0" />
      <mass value="2.79255049" />
      <inertia ixx="0.0281614102" ixy="-2.07379804e-05" ixz="-0.0150578544" iyy="0.039793871" iyz="-1.25290185e-05" izz="0.025600094" />
    </inertial>
  </link>
  <joint name="joint_1_2" type="revolute">
    <parent link="link_1" />
    <child link="link_2" />
    <origin xyz="0.687455089 0.00273809246 -0.506032737" rpy="0 0 0" />
    <axis xyz="0.0121977672 0.0124894903 -0.999847602" />
    <limit lower="-1.57" upper="1.57" effort="10.0" velocity="1.0" />
  </joint>
  <joint name="joint_2_3" type="revolute">
    <parent link="link_2" />
    <child link="link_3" />
    <origin xyz="-0.395280999 -0.000372283085 0.990630132" rpy="0 0 0" />
    <axis xyz="-0.00578407356 0.99995203 0.00790457209" />
    <limit lower="-1.57" upper="1.57" effort="10.0" velocity="1.0" />
  </joint>
  <joint name="joint_3_4" type="revolute">
    <parent link="link_3" />
    <child link="link_4" />
    <origin xyz="-0.894936148 -0.0044325779 0.0941477071" rpy="0 0 0" />
    <axis xyz="0.0077309311 0.999949916 0.00635587935" />
    <limit lower="-1.57" upper="1.57" effort="10.0" velocity="1.0" />
  </joint>
  <joint name="base_to_1" type="fixed">
    <parent link="base" />
    <child link="link_1" />
    <origin xyz="0 0 0" rpy="0 0 0" />
  </joint>
</robot>