<?xml version='1.0' encoding='utf-8'?>
<robot name="object">
  <link name="base">
    <inertial>
      <origin xyz="0 0 0" rpy="0 0 0" />
      <mass value="0.0" />
      <inertia ixx="0" ixy="0" ixz="0" iyy="0" iyz="0" izz="0" />
    </inertial>
  </link>
  <link name="link_1">
    <visual>
      <origin xyz="0 0 0" rpy="0 0 0" />
      <geometry>
        <mesh filename="meshes/link_1.stl" />
      </geometry>
    </visual>
    <collision>
      <origin xyz="0 0 0" rpy="0 0 0" />
      <geometry>
        <mesh filename="meshes/link_1.stl" />
      </geometry>
    </collision>
    <inertial>
      <origin xyz="0.0173071256 -0.00129664342 0.316234422" rpy="0 0 0" />
      <mass value="43.5358565" />
      <inertia ixx="-0.325437105" ixy="0.00277721587" ixz="-0.00704071024" iyy="-0.121403717" iyz="0.000782956687" izz="0.506822194" />
    </inertial>
  </link>
  <link name="link_2">
    <visual>
      <origin xyz="-0.0441173237 0.00179261475 -0.706526953" rpy="0 0 0" />
      <geometry>
        <mesh filename="meshes/link_2.stl" />
      </geometry>
    </visual>
    <collision>
      <origin xyz="-0.0441173237 0.00179261475 -0.706526953" rpy="0 0 0" />
      <geometry>
        <mesh filename="meshes/link_2.stl" />
      </geometry>
    </collision>
    <inertial>
      <origin xyz="-0.019680273 -0.000944987298 3.68021151" rpy="0 0 0" />
      <mass value="3.69457185" />
      <inertia ixx="-21362.3658" ixy="0.000688798082" ixz="7.36049386" iyy="-21362.3466" iyz="0.046448535" izz="0.0246359082" />
    </inertial>
  </link>
  <link name="link_3">
    <visual>
      <origin xyz="0.0553239949 0.00216212618 -0.846435305" rpy="0 0 0" />
      <geometry>
        <mesh filename="meshes/link_3.stl" />
      </geometry>
    </visual>
    <collision>
      <origin xyz="0.0553239949 0.00216212618 -0.846435305" rpy="0 0 0" />
      <geometry>
        <mesh filename="meshes/link_3.stl" />
      </geometry>
    </collision>
    <inertial>
      <origin xyz="-0.069165509 0.00127877611 -0.0516825515" rpy="0 0 0" />
      <mass value="0.524493621" />
      <inertia ixx="0.000765516748" ixy="2.05392781e-05" ixz="-0.000457520652" iyy="0.00128942165" iyz="-7.2314641e-07" izz="0.000816878989" />
    </inertial>
  </link>
  <joint name="joint_1_2" type="revolute">
    <parent link="link_1" />
    <child link="link_2" />
    <origin xyz="0.0441173237 -0.00179261475 0.706526953" rpy="0 0 0" />
    <axis xyz="0.00672504529 0.00165376553 -0.999976019" />
    <limit lower="-1.57" upper="1.57" effort="10.0" velocity="1.0" />
  </joint>
  <joint name="joint_2_3" type="revolute">
    <parent link="link_2" />
    <child link="link_3" />
    <origin xyz="-0.0994413185 -0.000369511423 0.139908352" rpy="0 0 0" />
    <axis xyz="-0.00965232704 0.999945316 0.00402450058" />
    <limit lower="-1.57" upper="1.57" effort="10.0" velocity="1.0" />
  </joint>
  <joint name="base_to_1" type="fixed">
    <parent link="base" />
    <child link="link_1" />
    <origin xyz="0 0 0" rpy="0 0 0" />
  </joint>
</robot>