<?xml version='1.0' encoding='utf-8'?>
<robot name="object">
  <link name="base">
    <inertial>
      <origin xyz="0 0 0" rpy="0 0 0" />
      <mass value="0.0" />
      <inertia ixx="0" ixy="0" ixz="0" iyy="0" iyz="0" izz="0" />
    </inertial>
  </link>
  <link name="link_1">
    <visual>
      <origin xyz="0 0 0" rpy="0 0 0" />
      <geometry>
        <mesh filename="meshes/link_1.stl" />
      </geometry>
    </visual>
    <collision>
      <origin xyz="0 0 0" rpy="0 0 0" />
      <geometry>
        <mesh filename="meshes/link_1.stl" />
      </geometry>
    </collision>
    <inertial>
      <origin xyz="0.47079362 -0.0102187093 -0.0011528437" rpy="0 0 0" />
      <mass value="116.82141" />
      <inertia ixx="4.56867963" ixy="-0.025759205" ixz="-0.0474412287" iyy="5.66817223" iyz="-0.00048460948" izz="9.01250098" />
    </inertial>
  </link>
  <link name="link_2">
    <visual>
      <origin xyz="0.184626082 0.0107083639 0.000530721691" rpy="0 0 0" />
      <geometry>
        <mesh filename="meshes/link_2.stl" />
      </geometry>
    </visual>
    <collision>
      <origin xyz="0.184626082 0.0107083639 0.000530721691" rpy="0 0 0" />
      <geometry>
        <mesh filename="meshes/link_2.stl" />
      </geometry>
    </collision>
    <inertial>
      <origin xyz="-0.323429335 -0.00439306918 -0.00179009624" rpy="0 0 0" />
      <mass value="82.9367594" />
      <inertia ixx="3.06562988" ixy="0.0124918213" ixz="0.0383457051" iyy="2.97271879" iyz="0.000657816297" izz="5.16934445" />
    </inertial>
  </link>
  <joint name="joint_1_2" type="prismatic">
    <parent link="link_1" />
    <child link="link_2" />
    <origin xyz="-0.184626082 -0.0107083639 -0.000530721691" rpy="0 0 0" />
    <axis xyz="0.999993176 -0.00121125393 -0.00349023658" />
    <limit lower="-1.57" upper="1.57" effort="10.0" velocity="1.0" />
  </joint>
  <joint name="base_to_1" type="fixed">
    <parent link="base" />
    <child link="link_1" />
    <origin xyz="0 0 0" rpy="0 0 0" />
  </joint>
</robot>