<?xml version="1.0" ?>
<robot name="partnet_33eec7387937e83b54d7082b34825ef0">
	<link name="base"/>
	<link name="link_0">
		<visual name="button-1">
			<origin xyz="0.43970134167816566 -0.5636205013744164 0.27999173164615954"/>
			<geometry>
				<mesh filename="textured_objs/original-7.obj"/>
			</geometry>
		</visual>
		<collision>
			<origin xyz="0.43970134167816566 -0.5636205013744164 0.27999173164615954"/>
			<geometry>
				<mesh filename="textured_objs/original-7.obj"/>
			</geometry>
		</collision>
	</link>
	<joint name="joint_0" type="revolute">
		<origin xyz="-0.43970134167816566 0.5636205013744164 -0.27999173164615954"/>
		<axis xyz="-0.6417824432178281 -0.017345656255379007 0.7666905658650205"/>
		<child link="link_0"/>
		<parent link="link_4"/>
		<limit lower="-0.0" upper="0.5717698629533422"/>
	</joint>
	<link name="link_1">
		<visual name="lid-2">
			<origin xyz="0 -0.08623833640126832 0.03936250156839384"/>
			<geometry>
				<mesh filename="textured_objs/original-8.obj"/>
			</geometry>
		</visual>
		<collision>
			<origin xyz="0 -0.08623833640126832 0.03936250156839384"/>
			<geometry>
				<mesh filename="textured_objs/original-8.obj"/>
			</geometry>
		</collision>
	</link>
	<joint name="joint_1" type="revolute">
		<origin xyz="0 0.08623833640126832 -0.03936250156839384"/>
		<axis xyz="-1 0 0"/>
		<child link="link_1"/>
		<parent link="link_4"/>
		<limit lower="-0.0" upper="1.710422666954443"/>
	</joint>
	<link name="link_2">
		<visual name="seat-3">
			<origin xyz="0 -0.08623833640126832 0.03936250156839384"/>
			<geometry>
				<mesh filename="textured_objs/original-9.obj"/>
			</geometry>
		</visual>
		<collision>
			<origin xyz="0 -0.08623833640126832 0.03936250156839384"/>
			<geometry>
				<mesh filename="textured_objs/original-9.obj"/>
			</geometry>
		</collision>
	</link>
	<joint name="joint_2" type="revolute">
		<origin xyz="0 0.08623833640126832 -0.03936250156839384"/>
		<axis xyz="-1 0 0"/>
		<child link="link_2"/>
		<parent link="link_4"/>
		<limit lower="-0.0" upper="1.710422666954443"/>
	</joint>
	<link name="link_3">
		<visual name="lid-4">
			<origin xyz="0.052322038705573115 -0.7277991002285853 0.5060995377345119"/>
			<geometry>
				<mesh filename="textured_objs/original-6.obj"/>
			</geometry>
		</visual>
		<collision>
			<origin xyz="0.052322038705573115 -0.7277991002285853 0.5060995377345119"/>
			<geometry>
				<mesh filename="textured_objs/original-6.obj"/>
			</geometry>
		</collision>
	</link>
	<joint name="joint_3" type="prismatic">
		<origin xyz="-0.052322038705573115 0.7277991002285853 -0.5060995377345119"/>
		<axis xyz="-0.005104721319804252 0.9996378663149093 -0.02642116669685537"/>
		<child link="link_3"/>
		<parent link="link_4"/>
		<limit lower="0" upper="0.02"/>
	</joint>
	<link name="link_4">
		<visual name="base_body-5">
			<origin xyz="0 0 0"/>
			<geometry>
				<mesh filename="textured_objs/original-4.obj"/>
			</geometry>
		</visual>
		<visual name="base_body-5">
			<origin xyz="0 0 0"/>
			<geometry>
				<mesh filename="textured_objs/original-3.obj"/>
			</geometry>
		</visual>
		<visual name="base_body-5">
			<origin xyz="0 0 0"/>
			<geometry>
				<mesh filename="textured_objs/original-2.obj"/>
			</geometry>
		</visual>
		<visual name="base_body-5">
			<origin xyz="0 0 0"/>
			<geometry>
				<mesh filename="textured_objs/original-5.obj"/>
			</geometry>
		</visual>
		<visual name="base_body-5">
			<origin xyz="0 0 0"/>
			<geometry>
				<mesh filename="textured_objs/original-11.obj"/>
			</geometry>
		</visual>
		<visual name="base_body-5">
			<origin xyz="0 0 0"/>
			<geometry>
				<mesh filename="textured_objs/original-1.obj"/>
			</geometry>
		</visual>
		<visual name="base_body-5">
			<origin xyz="0 0 0"/>
			<geometry>
				<mesh filename="textured_objs/original-10.obj"/>
			</geometry>
		</visual>
		<collision>
			<origin xyz="0 0 0"/>
			<geometry>
				<mesh filename="textured_objs/original-4.obj"/>
			</geometry>
		</collision>
		<collision>
			<origin xyz="0 0 0"/>
			<geometry>
				<mesh filename="textured_objs/original-3.obj"/>
			</geometry>
		</collision>
		<collision>
			<origin xyz="0 0 0"/>
			<geometry>
				<mesh filename="textured_objs/original-2.obj"/>
			</geometry>
		</collision>
		<collision>
			<origin xyz="0 0 0"/>
			<geometry>
				<mesh filename="textured_objs/original-5.obj"/>
			</geometry>
		</collision>
		<collision>
			<origin xyz="0 0 0"/>
			<geometry>
				<mesh filename="textured_objs/original-11.obj"/>
			</geometry>
		</collision>
		<collision>
			<origin xyz="0 0 0"/>
			<geometry>
				<mesh filename="textured_objs/original-1.obj"/>
			</geometry>
		</collision>
		<collision>
			<origin xyz="0 0 0"/>
			<geometry>
				<mesh filename="textured_objs/original-10.obj"/>
			</geometry>
		</collision>
	</link>
	<joint name="joint_4" type="fixed">
		<origin rpy="1.570796326794897 0 -1.570796326794897" xyz="0 0 0"/>
		<child link="link_4"/>
		<parent link="base"/>
	</joint>
</robot>
