<?xml version='1.0' encoding='utf-8'?>
<robot name="object">
  <link name="base">
    <inertial>
      <origin xyz="0 0 0" rpy="0 0 0" />
      <mass value="0.0" />
      <inertia ixx="0" ixy="0" ixz="0" iyy="0" iyz="0" izz="0" />
    </inertial>
  </link>
  <link name="link_1">
    <visual>
      <origin xyz="0 0 0" rpy="0 0 0" />
      <geometry>
        <mesh filename="meshes/link_1.stl" />
      </geometry>
    </visual>
    <collision>
      <origin xyz="0 0 0" rpy="0 0 0" />
      <geometry>
        <mesh filename="meshes/link_1.stl" />
      </geometry>
    </collision>
    <inertial>
      <origin xyz="0.0103458504 -0.0473929552 0.726105831" rpy="0 0 0" />
      <mass value="354.952542" />
      <inertia ixx="-35.5537213" ixy="0.653095199" ixz="2.40081813" iyy="-34.6507365" iyz="2.27474612" izz="15.9813725" />
    </inertial>
  </link>
  <link name="link_2">
    <visual>
      <origin xyz="-0.0545027212 0.0553680067 -1.54244994" rpy="0 0 0" />
      <geometry>
        <mesh filename="meshes/link_2.stl" />
      </geometry>
    </visual>
    <collision>
      <origin xyz="-0.0545027212 0.0553680067 -1.54244994" rpy="0 0 0" />
      <geometry>
        <mesh filename="meshes/link_2.stl" />
      </geometry>
    </collision>
    <inertial>
      <origin xyz="0.0843133724 0.00524980527 26.6081391" rpy="0 0 0" />
      <mass value="1.48514383" />
      <inertia ixx="-89388487.7" ixy="-0.000204116176" ixz="948.75874" iyy="-89388487.7" iyz="-14.7139268" izz="0.0193824242" />
    </inertial>
  </link>
  <joint name="joint_1_2" type="revolute">
    <parent link="link_1" />
    <child link="link_2" />
    <origin xyz="0.0545027212 -0.0553680067 1.54244994" rpy="0 0 0" />
    <axis xyz="0.0138476145 -0.999891787 0.00496567636" />
    <limit lower="-1.57" upper="1.57" effort="10.0" velocity="1.0" />
  </joint>
  <joint name="base_to_1" type="fixed">
    <parent link="base" />
    <child link="link_1" />
    <origin xyz="0 0 0" rpy="0 0 0" />
  </joint>
</robot>