<?xml version='1.0' encoding='utf-8'?>
<robot name="object">
  <link name="base">
    <inertial>
      <origin xyz="0 0 0" rpy="0 0 0" />
      <mass value="0.0" />
      <inertia ixx="0" ixy="0" ixz="0" iyy="0" iyz="0" izz="0" />
    </inertial>
  </link>
  <link name="link_1">
    <visual>
      <origin xyz="0 0 0" rpy="0 0 0" />
      <geometry>
        <mesh filename="meshes/link_1.stl" />
      </geometry>
    </visual>
    <collision>
      <origin xyz="0 0 0" rpy="0 0 0" />
      <geometry>
        <mesh filename="meshes/link_1.stl" />
      </geometry>
    </collision>
    <inertial>
      <origin xyz="0.253461079 0.060911103 0.0535149727" rpy="0 0 0" />
      <mass value="276.28111" />
      <inertia ixx="62.2606749" ixy="4.18795273" ixz="1.28292402" iyy="51.1602419" iyz="0.18568624" izz="48.8230143" />
    </inertial>
  </link>
  <link name="link_2">
    <visual>
      <origin xyz="0.276042128 0.381241422 -0.0189477574" rpy="0 0 0" />
      <geometry>
        <mesh filename="meshes/link_2.stl" />
      </geometry>
    </visual>
    <collision>
      <origin xyz="0.276042128 0.381241422 -0.0189477574" rpy="0 0 0" />
      <geometry>
        <mesh filename="meshes/link_2.stl" />
      </geometry>
    </collision>
    <inertial>
      <origin xyz="-0.505476995 0.223091021 0.00604531852" rpy="0 0 0" />
      <mass value="58.1384504" />
      <inertia ixx="10.7415046" ixy="2.92826154" ixz="0.00569950063" iyy="10.9273195" iyz="0.00506908859" izz="6.33711148" />
    </inertial>
  </link>
  <link name="link_3">
    <visual>
      <origin xyz="0.627862795 0.160299818 -0.0565293281" rpy="0 0 0" />
      <geometry>
        <mesh filename="meshes/link_3.stl" />
      </geometry>
    </visual>
    <collision>
      <origin xyz="0.627862795 0.160299818 -0.0565293281" rpy="0 0 0" />
      <geometry>
        <mesh filename="meshes/link_3.stl" />
      </geometry>
    </collision>
    <inertial>
      <origin xyz="-0.0231761331 -0.0275868358 -0.00447578145" rpy="0 0 0" />
      <mass value="1.22723536" />
      <inertia ixx="0.00694190326" ixy="0.00166785409" ixz="-2.1806177e-05" iyy="0.00705786636" iyz="-7.52421648e-05" izz="0.00505690801" />
    </inertial>
  </link>
  <joint name="joint_1_2" type="revolute">
    <parent link="link_1" />
    <child link="link_2" />
    <origin xyz="-0.276042128 -0.381241422 0.0189477574" rpy="0 0 0" />
    <axis xyz="-0.000345670455 0.00703044828 0.999975226" />
    <limit lower="-1.57" upper="1.57" effort="10.0" velocity="1.0" />
  </joint>
  <joint name="joint_2_3" type="revolute">
    <parent link="link_2" />
    <child link="link_3" />
    <origin xyz="-0.351820667 0.220941604 0.0375815708" rpy="0 0 0" />
    <axis xyz="0.70694794 0.707264481 -0.00125093872" />
    <limit lower="-1.57" upper="1.57" effort="10.0" velocity="1.0" />
  </joint>
  <joint name="base_to_1" type="fixed">
    <parent link="base" />
    <child link="link_1" />
    <origin xyz="0 0 0" rpy="0 0 0" />
  </joint>
</robot>