<?xml version='1.0' encoding='utf-8'?>
<robot name="object">
  <link name="base">
    <inertial>
      <origin xyz="0 0 0" rpy="0 0 0" />
      <mass value="0.0" />
      <inertia ixx="0" ixy="0" ixz="0" iyy="0" iyz="0" izz="0" />
    </inertial>
  </link>
  <link name="link_1">
    <visual>
      <origin xyz="0 0 0" rpy="0 0 0" />
      <geometry>
        <mesh filename="meshes/link_1.stl" />
      </geometry>
    </visual>
    <collision>
      <origin xyz="0 0 0" rpy="0 0 0" />
      <geometry>
        <mesh filename="meshes/link_1.stl" />
      </geometry>
    </collision>
    <inertial>
      <origin xyz="0.0173857514 0.000419991881 0.318694749" rpy="0 0 0" />
      <mass value="38.2261949" />
      <inertia ixx="-0.546795582" ixy="-0.010869197" ixz="0.00200410714" iyy="-0.544678617" iyz="-0.0243565377" izz="0.384876491" />
    </inertial>
  </link>
  <link name="link_2">
    <visual>
      <origin xyz="-0.023454612 -0.0106402766 -0.634624024" rpy="0 0 0" />
      <geometry>
        <mesh filename="meshes/link_2.stl" />
      </geometry>
    </visual>
    <collision>
      <origin xyz="-0.023454612 -0.0106402766 -0.634624024" rpy="0 0 0" />
      <geometry>
        <mesh filename="meshes/link_2.stl" />
      </geometry>
    </collision>
    <inertial>
      <origin xyz="0.000174482365 -0.0126442833 2.1238007" rpy="0 0 0" />
      <mass value="11.9412305" />
      <inertia ixx="-5155.47265" ixy="0.000498020342" ixz="-1.75033388" iyy="-5155.44961" iyz="0.00852166092" izz="0.131661686" />
    </inertial>
  </link>
  <link name="link_3">
    <visual>
      <origin xyz="0.0480141213 -0.00318566215 -0.881430138" rpy="0 0 0" />
      <geometry>
        <mesh filename="meshes/link_3.stl" />
      </geometry>
    </visual>
    <collision>
      <origin xyz="0.0480141213 -0.00318566215 -0.881430138" rpy="0 0 0" />
      <geometry>
        <mesh filename="meshes/link_3.stl" />
      </geometry>
    </collision>
    <inertial>
      <origin xyz="0.100370718 -0.0119813055 9.00383846" rpy="0 0 0" />
      <mass value="0.982597477" />
      <inertia ixx="-810566.744" ixy="0.000225252859" ixz="85.8923386" iyy="-810566.742" iyz="-0.0480350525" izz="0.00410554351" />
    </inertial>
  </link>
  <joint name="joint_1_2" type="revolute">
    <parent link="link_1" />
    <child link="link_2" />
    <origin xyz="0.023454612 0.0106402766 0.634624024" rpy="0 0 0" />
    <axis xyz="0.000968485304 -0.000449219502 -0.99999943" />
    <limit lower="-1.57" upper="1.57" effort="10.0" velocity="1.0" />
  </joint>
  <joint name="joint_2_3" type="revolute">
    <parent link="link_2" />
    <child link="link_3" />
    <origin xyz="-0.0714687334 -0.00745461445 0.246806115" rpy="0 0 0" />
    <axis xyz="-0.00540993742 -0.999984964 0.000896880387" />
    <limit lower="-1.57" upper="1.57" effort="10.0" velocity="1.0" />
  </joint>
  <joint name="base_to_1" type="fixed">
    <parent link="base" />
    <child link="link_1" />
    <origin xyz="0 0 0" rpy="0 0 0" />
  </joint>
</robot>