<?xml version='1.0' encoding='utf-8'?>
<robot name="object">
  <link name="base">
    <inertial>
      <origin xyz="0 0 0" rpy="0 0 0" />
      <mass value="0.0" />
      <inertia ixx="0" ixy="0" ixz="0" iyy="0" iyz="0" izz="0" />
    </inertial>
  </link>
  <link name="link_1">
    <visual>
      <origin xyz="0 0 0" rpy="0 0 0" />
      <geometry>
        <mesh filename="meshes/link_1.stl" />
      </geometry>
    </visual>
    <collision>
      <origin xyz="0 0 0" rpy="0 0 0" />
      <geometry>
        <mesh filename="meshes/link_1.stl" />
      </geometry>
    </collision>
    <inertial>
      <origin xyz="-0.00645057359 0.0103344286 0.136476689" rpy="0 0 0" />
      <mass value="27.5595961" />
      <inertia ixx="0.179996241" ixy="0.00107246947" ixz="-0.0212180309" iyy="0.186667239" iyz="-0.0100819853" izz="0.386559975" />
    </inertial>
  </link>
  <link name="link_2">
    <visual>
      <origin xyz="0.0327555514 0.159762832 -0.400378812" rpy="0 0 0" />
      <geometry>
        <mesh filename="meshes/link_2.stl" />
      </geometry>
    </visual>
    <collision>
      <origin xyz="0.0327555514 0.159762832 -0.400378812" rpy="0 0 0" />
      <geometry>
        <mesh filename="meshes/link_2.stl" />
      </geometry>
    </collision>
    <inertial>
      <origin xyz="0.00448704453 -0.00811564359 0.142906082" rpy="0 0 0" />
      <mass value="3.02526157" />
      <inertia ixx="0.0196862281" ixy="0.000185291671" ixz="-0.000726895738" iyy="0.0379048555" iyz="-0.00111131359" izz="0.0191874988" />
    </inertial>
  </link>
  <joint name="joint_1_2" type="revolute">
    <parent link="link_1" />
    <child link="link_2" />
    <origin xyz="-0.0327555514 -0.159762832 0.400378812" rpy="0 0 0" />
    <axis xyz="0.99970445 0.0112607711 0.0215454848" />
    <limit lower="-1.57" upper="1.57" effort="10.0" velocity="1.0" />
  </joint>
  <joint name="base_to_1" type="fixed">
    <parent link="base" />
    <child link="link_1" />
    <origin xyz="0 0 0" rpy="0 0 0" />
  </joint>
</robot>