<?xml version='1.0' encoding='utf-8'?>
<robot name="object">
  <link name="base">
    <inertial>
      <origin xyz="0 0 0" rpy="0 0 0" />
      <mass value="0.0" />
      <inertia ixx="0" ixy="0" ixz="0" iyy="0" iyz="0" izz="0" />
    </inertial>
  </link>
  <link name="link_1">
    <visual>
      <origin xyz="0 0 0" rpy="0 0 0" />
      <geometry>
        <mesh filename="meshes/link_1.stl" />
      </geometry>
    </visual>
    <collision>
      <origin xyz="0 0 0" rpy="0 0 0" />
      <geometry>
        <mesh filename="meshes/link_1.stl" />
      </geometry>
    </collision>
    <inertial>
      <origin xyz="0.257624778 -0.00765919935 -0.521438323" rpy="0 0 0" />
      <mass value="5.8668443" />
      <inertia ixx="0.331942369" ixy="0.00071836755" ixz="-0.201640037" iyy="-0.352191018" iyz="-0.0464801242" izz="0.891001798" />
    </inertial>
  </link>
  <link name="link_2">
    <visual>
      <origin xyz="0.0273353932 0.386319676 -0.0224581557" rpy="0 0 0" />
      <geometry>
        <mesh filename="meshes/link_2.stl" />
      </geometry>
    </visual>
    <collision>
      <origin xyz="0.0273353932 0.386319676 -0.0224581557" rpy="0 0 0" />
      <geometry>
        <mesh filename="meshes/link_2.stl" />
      </geometry>
    </collision>
    <inertial>
      <origin xyz="-0.0893305938 0.325293356 0.0109378753" rpy="0 0 0" />
      <mass value="17.3900955" />
      <inertia ixx="0.619849496" ixy="0.0152632378" ixz="-0.00104442457" iyy="1.07848189" iyz="-0.00288119579" izz="1.69214689" />
    </inertial>
  </link>
  <link name="link_3">
    <visual>
      <origin xyz="0.0232802673 0.417991665 -0.0340448326" rpy="0 0 0" />
      <geometry>
        <mesh filename="meshes/link_3.stl" />
      </geometry>
    </visual>
    <collision>
      <origin xyz="0.0232802673 0.417991665 -0.0340448326" rpy="0 0 0" />
      <geometry>
        <mesh filename="meshes/link_3.stl" />
      </geometry>
    </collision>
    <inertial>
      <origin xyz="0.070308711 0.425867804 0.108858503" rpy="0 0 0" />
      <mass value="19.9545671" />
      <inertia ixx="8.06516298" ixy="0.0165810562" ixz="-3.568355" iyy="7.58520608" iyz="0.0492585856" izz="5.55563966" />
    </inertial>
  </link>
  <joint name="joint_1_3" type="revolute">
    <parent link="link_1" />
    <child link="link_3" />
    <origin xyz="-0.0232802673 -0.417991665 0.0340448326" rpy="0 0 0" />
    <axis xyz="0.01196337 0.999928374 0.000352147113" />
    <limit lower="-1.57" upper="1.57" effort="10.0" velocity="1.0" />
  </joint>
  <joint name="joint_3_2" type="revolute">
    <parent link="link_3" />
    <child link="link_2" />
    <origin xyz="-0.00405512588 0.0316719887 -0.011586677" rpy="0 0 0" />
    <axis xyz="0.00439749921 0.999983803 0.00361314882" />
    <limit lower="-1.57" upper="1.57" effort="10.0" velocity="1.0" />
  </joint>
  <joint name="base_to_1" type="fixed">
    <parent link="base" />
    <child link="link_1" />
    <origin xyz="0 0 0" rpy="0 0 0" />
  </joint>
</robot>