<?xml version='1.0' encoding='utf-8'?>
<robot name="object">
  <link name="base">
    <inertial>
      <origin xyz="0 0 0" rpy="0 0 0" />
      <mass value="0.0" />
      <inertia ixx="0" ixy="0" ixz="0" iyy="0" iyz="0" izz="0" />
    </inertial>
  </link>
  <link name="link_1">
    <visual>
      <origin xyz="0 0 0" rpy="0 0 0" />
      <geometry>
        <mesh filename="meshes/link_1.stl" />
      </geometry>
    </visual>
    <collision>
      <origin xyz="0 0 0" rpy="0 0 0" />
      <geometry>
        <mesh filename="meshes/link_1.stl" />
      </geometry>
    </collision>
    <inertial>
      <origin xyz="0.0679376867 0.00297495771 -0.0174413585" rpy="0 0 0" />
      <mass value="411.995997" />
      <inertia ixx="77.7488634" ixy="-0.0692758181" ixz="-46.1805513" iyy="131.882674" iyz="-0.112178406" izz="86.9368796" />
    </inertial>
  </link>
  <link name="link_2">
    <visual>
      <origin xyz="-0.0423056701 0.000213782705 -0.0876036963" rpy="0 0 0" />
      <geometry>
        <mesh filename="meshes/link_2.stl" />
      </geometry>
    </visual>
    <collision>
      <origin xyz="-0.0423056701 0.000213782705 -0.0876036963" rpy="0 0 0" />
      <geometry>
        <mesh filename="meshes/link_2.stl" />
      </geometry>
    </collision>
    <inertial>
      <origin xyz="-0.359364826 0.00479776968 0.17011146" rpy="0 0 0" />
      <mass value="11.7321902" />
      <inertia ixx="0.812622318" ixy="-0.00121796596" ixz="0.355917072" iyy="0.785989238" iyz="0.00170550107" izz="1.2086571" />
    </inertial>
  </link>
  <link name="link_3">
    <visual>
      <origin xyz="-0.0700806833 -0.00585808732 -0.0880001275" rpy="0 0 0" />
      <geometry>
        <mesh filename="meshes/link_3.stl" />
      </geometry>
    </visual>
    <collision>
      <origin xyz="-0.0700806833 -0.00585808732 -0.0880001275" rpy="0 0 0" />
      <geometry>
        <mesh filename="meshes/link_3.stl" />
      </geometry>
    </collision>
    <inertial>
      <origin xyz="-0.186050777 -8.34069037e-05 0.327565965" rpy="0 0 0" />
      <mass value="23.035374" />
      <inertia ixx="0.246236957" ixy="-0.000484243372" ixz="-0.00469277478" iyy="-0.0433521147" iyz="0.009349146" izz="0.934786138" />
    </inertial>
  </link>
  <link name="link_4">
    <visual>
      <origin xyz="-0.426424517 0.000165591769 -0.618794232" rpy="0 0 0" />
      <geometry>
        <mesh filename="meshes/link_4.stl" />
      </geometry>
    </visual>
    <collision>
      <origin xyz="-0.426424517 0.000165591769 -0.618794232" rpy="0 0 0" />
      <geometry>
        <mesh filename="meshes/link_4.stl" />
      </geometry>
    </collision>
    <inertial>
      <origin xyz="-0.0279613447 0.00375537023 2.83223144" rpy="0 0 0" />
      <mass value="49.3769836" />
      <inertia ixx="-183465.905" ixy="0.0120543716" ixz="4.81793815" iyy="-183468.478" iyz="1.46445279" izz="3.76805256" />
    </inertial>
  </link>
  <joint name="joint_1_2" type="revolute">
    <parent link="link_1" />
    <child link="link_2" />
    <origin xyz="0.0423056701 -0.000213782705 0.0876036963" rpy="0 0 0" />
    <axis xyz="-0.0159254864 -0.999150903 -0.0379980429" />
    <limit lower="-1.57" upper="1.57" effort="10.0" velocity="1.0" />
  </joint>
  <joint name="joint_1_3" type="revolute">
    <parent link="link_1" />
    <child link="link_3" />
    <origin xyz="0.0700806833 0.00585808732 0.0880001275" rpy="0 0 0" />
    <axis xyz="-0.0159254864 -0.999150903 -0.0379980429" />
    <limit lower="-1.57" upper="1.57" effort="10.0" velocity="1.0" />
  </joint>
  <joint name="joint_1_4" type="prismatic">
    <parent link="link_1" />
    <child link="link_4" />
    <origin xyz="0.426424517 -0.000165591769 0.618794232" rpy="0 0 0" />
    <axis xyz="-0.0222161061 0.00106128673 -0.999752629" />
    <limit lower="-1.57" upper="1.57" effort="10.0" velocity="1.0" />
  </joint>
  <joint name="base_to_1" type="fixed">
    <parent link="base" />
    <child link="link_1" />
    <origin xyz="0 0 0" rpy="0 0 0" />
  </joint>
</robot>