<?xml version="1.0"?>
<robot  name="bucket" >
 <link  name="base" />
 <link  name="bucket_body" >
  <visual >
   <geometry >
    <mesh  filename="/mnt/users/hyeslee/codes/baselines/articulate-anything/datasets/partnet-mobility-v0/dataset/102352/textured_objs/original-8.obj" />
   </geometry>
   <origin  xyz="0 0 0"  rpy="0 0 0" />
  </visual>
  <visual >
   <geometry >
    <mesh  filename="/mnt/users/hyeslee/codes/baselines/articulate-anything/datasets/partnet-mobility-v0/dataset/102352/textured_objs/original-6.obj" />
   </geometry>
   <origin  xyz="0 0 0"  rpy="0 0 0" />
  </visual>
  <visual >
   <geometry >
    <mesh  filename="/mnt/users/hyeslee/codes/baselines/articulate-anything/datasets/partnet-mobility-v0/dataset/102352/textured_objs/original-7.obj" />
   </geometry>
   <origin  xyz="0 0 0"  rpy="0 0 0" />
  </visual>
  <collision >
   <geometry >
    <mesh  filename="/mnt/users/hyeslee/codes/baselines/articulate-anything/datasets/partnet-mobility-v0/dataset/102352/textured_objs/original-8.obj" />
   </geometry>
   <origin  xyz="0 0 0"  rpy="0 0 0" />
  </collision>
  <collision >
   <geometry >
    <mesh  filename="/mnt/users/hyeslee/codes/baselines/articulate-anything/datasets/partnet-mobility-v0/dataset/102352/textured_objs/original-6.obj" />
   </geometry>
   <origin  xyz="0 0 0"  rpy="0 0 0" />
  </collision>
  <collision >
   <geometry >
    <mesh  filename="/mnt/users/hyeslee/codes/baselines/articulate-anything/datasets/partnet-mobility-v0/dataset/102352/textured_objs/original-7.obj" />
   </geometry>
   <origin  xyz="0 0 0"  rpy="0 0 0" />
  </collision>
 </link>
 <joint  type="fixed"  name="base_to_bucket_body" >
  <parent  link="base" />
  <child  link="bucket_body" />
  <origin  xyz="0 0 0"  rpy="1.5707963267948961 0.0 1.5707963267948961" />
 </joint>
 <link  name="handle" >
  <visual >
   <geometry >
    <mesh  filename="/mnt/users/hyeslee/codes/baselines/articulate-anything/datasets/partnet-mobility-v0/dataset/102352/textured_objs/original-4.obj" />
   </geometry>
   <origin  xyz="-0.02657049894332871 -0.628373018741608 0.07521100276708644"  rpy="0 0 0" />
  </visual>
  <visual >
   <geometry >
    <mesh  filename="/mnt/users/hyeslee/codes/baselines/articulate-anything/datasets/partnet-mobility-v0/dataset/102352/textured_objs/original-2.obj" />
   </geometry>
   <origin  xyz="-0.02657049894332871 -0.628373018741608 0.07521100276708644"  rpy="0 0 0" />
  </visual>
  <visual >
   <geometry >
    <mesh  filename="/mnt/users/hyeslee/codes/baselines/articulate-anything/datasets/partnet-mobility-v0/dataset/102352/textured_objs/original-3.obj" />
   </geometry>
   <origin  xyz="-0.02657049894332871 -0.628373018741608 0.07521100276708644"  rpy="0 0 0" />
  </visual>
  <collision >
   <geometry >
    <mesh  filename="/mnt/users/hyeslee/codes/baselines/articulate-anything/datasets/partnet-mobility-v0/dataset/102352/textured_objs/original-4.obj" />
   </geometry>
   <origin  xyz="-0.02657049894332871 -0.628373018741608 0.07521100276708644"  rpy="0 0 0" />
  </collision>
  <collision >
   <geometry >
    <mesh  filename="/mnt/users/hyeslee/codes/baselines/articulate-anything/datasets/partnet-mobility-v0/dataset/102352/textured_objs/original-2.obj" />
   </geometry>
   <origin  xyz="-0.02657049894332871 -0.628373018741608 0.07521100276708644"  rpy="0 0 0" />
  </collision>
  <collision >
   <geometry >
    <mesh  filename="/mnt/users/hyeslee/codes/baselines/articulate-anything/datasets/partnet-mobility-v0/dataset/102352/textured_objs/original-3.obj" />
   </geometry>
   <origin  xyz="-0.02657049894332871 -0.628373018741608 0.07521100276708644"  rpy="0 0 0" />
  </collision>
 </link>
 <joint  type="revolute"  name="bucket_body_to_handle" >
  <parent  link="bucket_body" />
  <child  link="handle" />
  <axis  xyz="1.0 0.0 -4.440892098500626e-16" />
  <limit  velocity="5"  upper="1.7453292519943295"  effort="5"  lower="0.0" />
  <origin  xyz="0.02657049894332871 0.628373018741608 -0.07521100276708644" />
 </joint>
</robot>
