<?xml version='1.0' encoding='utf-8'?>
<robot name="object">
  <link name="base">
    <inertial>
      <origin xyz="0 0 0" rpy="0 0 0" />
      <mass value="0.0" />
      <inertia ixx="0" ixy="0" ixz="0" iyy="0" iyz="0" izz="0" />
    </inertial>
  </link>
  <link name="link_1">
    <visual>
      <origin xyz="0 0 0.680487752" rpy="0 0 0" />
      <geometry>
        <mesh filename="meshes/link_1.stl" />
      </geometry>
    </visual>
    <collision>
      <origin xyz="0 0 0.680487752" rpy="0 0 0" />
      <geometry>
        <mesh filename="meshes/link_1.stl" />
      </geometry>
    </collision>
    <inertial>
      <origin xyz="0.0265524849 -0.0234391734 0.667612729" rpy="0 0 0" />
      <mass value="281.840777" />
      <inertia ixx="100.429739" ixy="-0.0167552219" ixz="0.0537120247" iyy="101.670765" iyz="-0.108673892" izz="97.1469284" />
    </inertial>
  </link>
  <link name="link_2">
    <visual>
      <origin xyz="-0.026968776 -0.694366717 -0.572092519" rpy="0 0 0" />
      <geometry>
        <mesh filename="meshes/link_2.stl" />
      </geometry>
    </visual>
    <collision>
      <origin xyz="-0.026968776 -0.694366717 -0.572092519" rpy="0 0 0" />
      <geometry>
        <mesh filename="meshes/link_2.stl" />
      </geometry>
    </collision>
    <inertial>
      <origin xyz="-0.532994912 -0.727980616 0.902173859" rpy="0 0 0" />
      <mass value="10.0637241" />
      <inertia ixx="5.65813355" ixy="0.111222592" ixz="-1.73447032" iyy="2.33180695" iyz="0.0457833801" izz="5.08241464" />
    </inertial>
  </link>
  <joint name="joint_1_2" type="revolute">
    <parent link="link_1" />
    <child link="link_2" />
    <origin xyz="0.026968776 0.694366717 1.25258027" rpy="0 0 0" />
    <axis xyz="-0.00316817089 -0.9999947 0.000749841812" />
    <limit lower="-1.57" upper="1.57" effort="10.0" velocity="1.0" />
  </joint>
  <joint name="base_to_1" type="fixed">
    <parent link="base" />
    <child link="link_1" />
    <origin xyz="0 0 -0.680487752" rpy="0 0 0" />
  </joint>
</robot>