<?xml version="1.0" ?>
<robot name="partnet_77343b3052c4c5d0492d9da2668ec34c">
	<link name="base"/>
	<link name="link_0">
		<visual name="seat-1">
			<origin xyz="0 -0.0191501722664436 -0.02939885926269495"/>
			<geometry>
				<mesh filename="textured_objs/original-3.obj"/>
			</geometry>
		</visual>
		<collision>
			<origin xyz="0 -0.0191501722664436 -0.02939885926269495"/>
			<geometry>
				<mesh filename="textured_objs/original-3.obj"/>
			</geometry>
		</collision>
	</link>
	<joint name="joint_0" type="revolute">
		<origin xyz="0 0.0191501722664436 0.02939885926269495"/>
		<axis xyz="-1 0 0"/>
		<child link="link_0"/>
		<parent link="link_1"/>
		<limit lower="-0.0" upper="1.086991058142069"/>
	</joint>
	<link name="link_1">
		<visual name="backlegs-2">
			<origin xyz="0 0 0"/>
			<geometry>
				<mesh filename="textured_objs/original-2.obj"/>
			</geometry>
		</visual>
		<collision>
			<origin xyz="0 0 0"/>
			<geometry>
				<mesh filename="textured_objs/original-2.obj"/>
			</geometry>
		</collision>
	</link>
	<joint name="joint_1" type="fixed">
		<origin rpy="1.570796326794897 0 -1.570796326794897" xyz="0 0 0"/>
		<child link="link_1"/>
		<parent link="base"/>
	</joint>
	<link name="link_2">
		<visual name="base_body-3">
			<origin xyz="0 -0.0191501722664436 -0.02939885926269495"/>
			<geometry>
				<mesh filename="textured_objs/original-1.obj"/>
			</geometry>
		</visual>
		<collision>
			<origin xyz="0 -0.0191501722664436 -0.02939885926269495"/>
			<geometry>
				<mesh filename="textured_objs/original-1.obj"/>
			</geometry>
		</collision>
	</link>
	<joint name="joint_2" type="revolute">
		<origin xyz="0 0.0191501722664436 0.02939885926269495"/>
		<axis xyz="1 0 0"/>
		<child link="link_2"/>
		<parent link="link_1"/>
		<limit lower="0.0" upper="1.1184069846779663"/>
	</joint>
</robot>
