<?xml version='1.0' encoding='utf-8'?>
<robot name="object">
  <link name="base">
    <inertial>
      <origin xyz="0 0 0" rpy="0 0 0" />
      <mass value="0.0" />
      <inertia ixx="0" ixy="0" ixz="0" iyy="0" iyz="0" izz="0" />
    </inertial>
  </link>
  <link name="link_1">
    <visual>
      <origin xyz="0 0 0" rpy="0 0 0" />
      <geometry>
        <mesh filename="meshes/link_1.stl" />
      </geometry>
    </visual>
    <collision>
      <origin xyz="0 0 0" rpy="0 0 0" />
      <geometry>
        <mesh filename="meshes/link_1.stl" />
      </geometry>
    </collision>
    <inertial>
      <origin xyz="-0.0424699416 0.0508556479 0.0290919629" rpy="0 0 0" />
      <mass value="63.4959616" />
      <inertia ixx="5.74989376" ixy="0.359228396" ixz="-0.000934944949" iyy="8.65740575" iyz="0.052319821" izz="14.4766654" />
    </inertial>
  </link>
  <link name="link_2">
    <visual>
      <origin xyz="-0.0343776686 -0.449040032 -0.0366234868" rpy="0 0 0" />
      <geometry>
        <mesh filename="meshes/link_2.stl" />
      </geometry>
    </visual>
    <collision>
      <origin xyz="-0.0343776686 -0.449040032 -0.0366234868" rpy="0 0 0" />
      <geometry>
        <mesh filename="meshes/link_2.stl" />
      </geometry>
    </collision>
    <inertial>
      <origin xyz="-0.00972413696 0.156310209 0.397853628" rpy="0 0 0" />
      <mass value="36.8228652" />
      <inertia ixx="-2.23984043" ixy="-0.0348957756" ixz="0.66580396" iyy="2.36730479" iyz="-0.586172289" izz="5.19464512" />
    </inertial>
  </link>
  <joint name="joint_1_2" type="revolute">
    <parent link="link_1" />
    <child link="link_2" />
    <origin xyz="0.0343776686 0.449040032 0.0366234868" rpy="0 0 0" />
    <axis xyz="-0.999956278 0.00477923137 0.00803745621" />
    <limit lower="-1.57" upper="1.57" effort="10.0" velocity="1.0" />
  </joint>
  <joint name="base_to_1" type="fixed">
    <parent link="base" />
    <child link="link_1" />
    <origin xyz="0 0 0" rpy="0 0 0" />
  </joint>
</robot>