<?xml version="1.0"?>
<robot  name="toilet" >
 <link  name="base" />
 <link  name="toilet_body" >
  <visual >
   <geometry >
    <mesh  filename="/mnt/users/hyeslee/codes/baselines/articulate-anything/datasets/partnet-mobility-v0/dataset/102667/textured_objs/original-8.obj" />
   </geometry>
   <origin  rpy="0 0 0"  xyz="0 0 0" />
  </visual>
  <visual >
   <geometry >
    <mesh  filename="/mnt/users/hyeslee/codes/baselines/articulate-anything/datasets/partnet-mobility-v0/dataset/102667/textured_objs/original-13.obj" />
   </geometry>
   <origin  rpy="0 0 0"  xyz="0 0 0" />
  </visual>
  <visual >
   <geometry >
    <mesh  filename="/mnt/users/hyeslee/codes/baselines/articulate-anything/datasets/partnet-mobility-v0/dataset/102667/textured_objs/original-6.obj" />
   </geometry>
   <origin  rpy="0 0 0"  xyz="0 0 0" />
  </visual>
  <visual >
   <geometry >
    <mesh  filename="/mnt/users/hyeslee/codes/baselines/articulate-anything/datasets/partnet-mobility-v0/dataset/102667/textured_objs/original-11.obj" />
   </geometry>
   <origin  rpy="0 0 0"  xyz="0 0 0" />
  </visual>
  <visual >
   <geometry >
    <mesh  filename="/mnt/users/hyeslee/codes/baselines/articulate-anything/datasets/partnet-mobility-v0/dataset/102667/textured_objs/original-12.obj" />
   </geometry>
   <origin  rpy="0 0 0"  xyz="0 0 0" />
  </visual>
  <visual >
   <geometry >
    <mesh  filename="/mnt/users/hyeslee/codes/baselines/articulate-anything/datasets/partnet-mobility-v0/dataset/102667/textured_objs/original-7.obj" />
   </geometry>
   <origin  rpy="0 0 0"  xyz="0 0 0" />
  </visual>
  <collision >
   <geometry >
    <mesh  filename="/mnt/users/hyeslee/codes/baselines/articulate-anything/datasets/partnet-mobility-v0/dataset/102667/textured_objs/original-8.obj" />
   </geometry>
   <origin  rpy="0 0 0"  xyz="0 0 0" />
  </collision>
  <collision >
   <geometry >
    <mesh  filename="/mnt/users/hyeslee/codes/baselines/articulate-anything/datasets/partnet-mobility-v0/dataset/102667/textured_objs/original-13.obj" />
   </geometry>
   <origin  rpy="0 0 0"  xyz="0 0 0" />
  </collision>
  <collision >
   <geometry >
    <mesh  filename="/mnt/users/hyeslee/codes/baselines/articulate-anything/datasets/partnet-mobility-v0/dataset/102667/textured_objs/original-6.obj" />
   </geometry>
   <origin  rpy="0 0 0"  xyz="0 0 0" />
  </collision>
  <collision >
   <geometry >
    <mesh  filename="/mnt/users/hyeslee/codes/baselines/articulate-anything/datasets/partnet-mobility-v0/dataset/102667/textured_objs/original-11.obj" />
   </geometry>
   <origin  rpy="0 0 0"  xyz="0 0 0" />
  </collision>
  <collision >
   <geometry >
    <mesh  filename="/mnt/users/hyeslee/codes/baselines/articulate-anything/datasets/partnet-mobility-v0/dataset/102667/textured_objs/original-12.obj" />
   </geometry>
   <origin  rpy="0 0 0"  xyz="0 0 0" />
  </collision>
  <collision >
   <geometry >
    <mesh  filename="/mnt/users/hyeslee/codes/baselines/articulate-anything/datasets/partnet-mobility-v0/dataset/102667/textured_objs/original-7.obj" />
   </geometry>
   <origin  rpy="0 0 0"  xyz="0 0 0" />
  </collision>
 </link>
 <joint  name="base_to_toilet_body"  type="fixed" >
  <parent  link="base" />
  <child  link="toilet_body" />
  <origin  rpy="1.5707963267948961 0.0 1.5707963267948961"  xyz="0 0 0" />
 </joint>
 <link  name="seat" >
  <visual >
   <geometry >
    <mesh  filename="/mnt/users/hyeslee/codes/baselines/articulate-anything/datasets/partnet-mobility-v0/dataset/102667/textured_objs/original-16.obj" />
   </geometry>
   <origin  rpy="0 0 0"  xyz="0 0 0" />
  </visual>
  <visual >
   <geometry >
    <mesh  filename="/mnt/users/hyeslee/codes/baselines/articulate-anything/datasets/partnet-mobility-v0/dataset/102667/textured_objs/original-15.obj" />
   </geometry>
   <origin  rpy="0 0 0"  xyz="0 0 0" />
  </visual>
  <collision >
   <geometry >
    <mesh  filename="/mnt/users/hyeslee/codes/baselines/articulate-anything/datasets/partnet-mobility-v0/dataset/102667/textured_objs/original-16.obj" />
   </geometry>
   <origin  rpy="0 0 0"  xyz="0 0 0" />
  </collision>
  <collision >
   <geometry >
    <mesh  filename="/mnt/users/hyeslee/codes/baselines/articulate-anything/datasets/partnet-mobility-v0/dataset/102667/textured_objs/original-15.obj" />
   </geometry>
   <origin  rpy="0 0 0"  xyz="0 0 0" />
  </collision>
 </link>
 <joint  name="toilet_body_to_seat"  type="fixed" >
  <parent  link="toilet_body" />
  <child  link="seat" />
  <origin  xyz="0.0 -0.0017540220618247095 -7.789422714953129e-19" />
 </joint>
 <link  name="lid" >
  <visual >
   <geometry >
    <mesh  filename="/mnt/users/hyeslee/codes/baselines/articulate-anything/datasets/partnet-mobility-v0/dataset/102667/textured_objs/original-19.obj" />
   </geometry>
   <origin  rpy="0 0 0"  xyz="0.3193479993343354 -0.05073000183701529 0.08330599898099936" />
  </visual>
  <visual >
   <geometry >
    <mesh  filename="/mnt/users/hyeslee/codes/baselines/articulate-anything/datasets/partnet-mobility-v0/dataset/102667/textured_objs/original-18.obj" />
   </geometry>
   <origin  rpy="0 0 0"  xyz="0.3193479993343354 -0.05073000183701529 0.08330599898099936" />
  </visual>
  <collision >
   <geometry >
    <mesh  filename="/mnt/users/hyeslee/codes/baselines/articulate-anything/datasets/partnet-mobility-v0/dataset/102667/textured_objs/original-19.obj" />
   </geometry>
   <origin  rpy="0 0 0"  xyz="0.3193479993343354 -0.05073000183701529 0.08330599898099936" />
  </collision>
  <collision >
   <geometry >
    <mesh  filename="/mnt/users/hyeslee/codes/baselines/articulate-anything/datasets/partnet-mobility-v0/dataset/102667/textured_objs/original-18.obj" />
   </geometry>
   <origin  rpy="0 0 0"  xyz="0.3193479993343354 -0.05073000183701529 0.08330599898099936" />
  </collision>
 </link>
 <link  name="pump_lid" >
  <visual >
   <geometry >
    <mesh  filename="/mnt/users/hyeslee/codes/baselines/articulate-anything/datasets/partnet-mobility-v0/dataset/102667/textured_objs/original-4.obj" />
   </geometry>
   <origin  rpy="0 0 0"  xyz="0 0 0" />
  </visual>
  <visual >
   <geometry >
    <mesh  filename="/mnt/users/hyeslee/codes/baselines/articulate-anything/datasets/partnet-mobility-v0/dataset/102667/textured_objs/original-3.obj" />
   </geometry>
   <origin  rpy="0 0 0"  xyz="0 0 0" />
  </visual>
  <collision >
   <geometry >
    <mesh  filename="/mnt/users/hyeslee/codes/baselines/articulate-anything/datasets/partnet-mobility-v0/dataset/102667/textured_objs/original-4.obj" />
   </geometry>
   <origin  rpy="0 0 0"  xyz="0 0 0" />
  </collision>
  <collision >
   <geometry >
    <mesh  filename="/mnt/users/hyeslee/codes/baselines/articulate-anything/datasets/partnet-mobility-v0/dataset/102667/textured_objs/original-3.obj" />
   </geometry>
   <origin  rpy="0 0 0"  xyz="0 0 0" />
  </collision>
 </link>
 <joint  name="toilet_body_to_pump_lid"  type="fixed" >
  <parent  link="toilet_body" />
  <child  link="pump_lid" />
  <origin  xyz="0.0 0.020351980209351257 9.038094810054912e-18" />
 </joint>
 <link  name="lever" >
  <visual >
   <geometry >
    <mesh  filename="/mnt/users/hyeslee/codes/baselines/articulate-anything/datasets/partnet-mobility-v0/dataset/102667/textured_objs/original-9.obj" />
   </geometry>
   <origin  rpy="0 0 0"  xyz="0 0 0" />
  </visual>
  <collision >
   <geometry >
    <mesh  filename="/mnt/users/hyeslee/codes/baselines/articulate-anything/datasets/partnet-mobility-v0/dataset/102667/textured_objs/original-9.obj" />
   </geometry>
   <origin  rpy="0 0 0"  xyz="0 0 0" />
  </collision>
 </link>
 <joint  name="toilet_body_to_lever"  type="fixed" >
  <parent  link="toilet_body" />
  <child  link="lever" />
  <origin  xyz="0.7860039992332459 0.0 -3.490558949584814e-16" />
 </joint>
 <joint  name="seat_to_lid"  type="revolute" >
  <parent  link="seat" />
  <child  link="lid" />
  <axis  xyz="-1.0 0.0 4.440892098500626e-16" />
  <limit  effort="5"  velocity="5"  upper="1.5707963267948966"  lower="0.0" />
  <origin  xyz="-0.3193479993343354 0.06125899875164068 -0.08330599898099936" />
 </joint>
</robot>
