<?xml version='1.0' encoding='utf-8'?>
<robot name="object">
  <link name="base">
    <inertial>
      <origin xyz="0 0 0" rpy="0 0 0" />
      <mass value="0.0" />
      <inertia ixx="0" ixy="0" ixz="0" iyy="0" iyz="0" izz="0" />
    </inertial>
  </link>
  <link name="link_1">
    <visual>
      <origin xyz="0 0 0" rpy="0 0 0" />
      <geometry>
        <mesh filename="meshes/link_1.stl" />
      </geometry>
    </visual>
    <collision>
      <origin xyz="0 0 0" rpy="0 0 0" />
      <geometry>
        <mesh filename="meshes/link_1.stl" />
      </geometry>
    </collision>
    <inertial>
      <origin xyz="0.187401576 -0.00643554864 -0.438594943" rpy="0 0 0" />
      <mass value="23.1300747" />
      <inertia ixx="0.326292143" ixy="-0.00454564579" ixz="0.000836979213" iyy="0.165267841" iyz="0.00687861294" izz="0.283761181" />
    </inertial>
  </link>
  <link name="link_2">
    <visual>
      <origin xyz="-0.175869532 -0.294052897 0.405940895" rpy="0 0 0" />
      <geometry>
        <mesh filename="meshes/link_2.stl" />
      </geometry>
    </visual>
    <collision>
      <origin xyz="-0.175869532 -0.294052897 0.405940895" rpy="0 0 0" />
      <geometry>
        <mesh filename="meshes/link_2.stl" />
      </geometry>
    </collision>
    <inertial>
      <origin xyz="0.00983647186 0.235634115 0.00333659218" rpy="0 0 0" />
      <mass value="3.21052468" />
      <inertia ixx="0.0498487764" ixy="-0.000213581145" ixz="2.9785961e-07" iyy="0.0315777946" iyz="0.00138883254" izz="0.0498527349" />
    </inertial>
  </link>
  <link name="link_3">
    <visual>
      <origin xyz="-0.203196382 0.285313708 0.40784755" rpy="0 0 0" />
      <geometry>
        <mesh filename="meshes/link_3.stl" />
      </geometry>
    </visual>
    <collision>
      <origin xyz="-0.203196382 0.285313708 0.40784755" rpy="0 0 0" />
      <geometry>
        <mesh filename="meshes/link_3.stl" />
      </geometry>
    </collision>
    <inertial>
      <origin xyz="-0.0205271419 -0.111844294 0.00273155309" rpy="0 0 0" />
      <mass value="3.30558731" />
      <inertia ixx="0.0176928478" ixy="-0.000259273081" ixz="1.69456229e-05" iyy="0.0316036504" iyz="-0.00030752939" izz="0.0177538117" />
    </inertial>
  </link>
  <link name="link_4">
    <visual>
      <origin xyz="-0.184883707 -8.19395484e-05 0.17917893" rpy="0 0 0" />
      <geometry>
        <mesh filename="meshes/link_4.stl" />
      </geometry>
    </visual>
    <collision>
      <origin xyz="-0.184883707 -8.19395484e-05 0.17917893" rpy="0 0 0" />
      <geometry>
        <mesh filename="meshes/link_4.stl" />
      </geometry>
    </collision>
    <inertial>
      <origin xyz="0.41086791 0.00069784592 0.672862242" rpy="0 0 0" />
      <mass value="33.6038661" />
      <inertia ixx="2.55543868" ixy="-0.00299653739" ixz="-1.69591763" iyy="7.6292034" iyz="-0.00312031628" izz="5.162784" />
    </inertial>
  </link>
  <joint name="joint_1_2" type="revolute">
    <parent link="link_1" />
    <child link="link_2" />
    <origin xyz="0.175869532 0.294052897 -0.405940895" rpy="0 0 0" />
    <axis xyz="0.0260056438 -0.999640524 -0.00652144134" />
    <limit lower="-1.57" upper="1.57" effort="10.0" velocity="1.0" />
  </joint>
  <joint name="joint_1_3" type="revolute">
    <parent link="link_1" />
    <child link="link_3" />
    <origin xyz="0.203196382 -0.285313708 -0.40784755" rpy="0 0 0" />
    <axis xyz="-0.11625947 0.993122322 -0.0138488082" />
    <limit lower="-1.57" upper="1.57" effort="10.0" velocity="1.0" />
  </joint>
  <joint name="joint_1_4" type="revolute">
    <parent link="link_1" />
    <child link="link_4" />
    <origin xyz="0.184883707 8.19395484e-05 -0.17917893" rpy="0 0 0" />
    <axis xyz="0.042936658 -0.0118939059 -0.999006996" />
    <limit lower="-1.57" upper="1.57" effort="10.0" velocity="1.0" />
  </joint>
  <joint name="base_to_1" type="fixed">
    <parent link="base" />
    <child link="link_1" />
    <origin xyz="0 0 0" rpy="0 0 0" />
  </joint>
</robot>