<?xml version='1.0' encoding='utf-8'?>
<robot name="object">
  <link name="base">
    <inertial>
      <origin xyz="0 0 0" rpy="0 0 0" />
      <mass value="0.0" />
      <inertia ixx="0" ixy="0" ixz="0" iyy="0" iyz="0" izz="0" />
    </inertial>
  </link>
  <link name="link_1">
    <visual>
      <origin xyz="0 0 0" rpy="0 0 0" />
      <geometry>
        <mesh filename="meshes/link_1.stl" />
      </geometry>
    </visual>
    <collision>
      <origin xyz="0 0 0" rpy="0 0 0" />
      <geometry>
        <mesh filename="meshes/link_1.stl" />
      </geometry>
    </collision>
    <inertial>
      <origin xyz="0.23995687 0.0285566408 0.0273525866" rpy="0 0 0" />
      <mass value="16.0218441" />
      <inertia ixx="0.454655734" ixy="-0.00398682659" ixz="0.000753750309" iyy="0.832298016" iyz="-0.00177140392" izz="1.2996348" />
    </inertial>
  </link>
  <link name="link_2">
    <visual>
      <origin xyz="-0.0172239204 -0.0133358395 -0.0818112754" rpy="0 0 0" />
      <geometry>
        <mesh filename="meshes/link_2.stl" />
      </geometry>
    </visual>
    <collision>
      <origin xyz="-0.0172239204 -0.0133358395 -0.0818112754" rpy="0 0 0" />
      <geometry>
        <mesh filename="meshes/link_2.stl" />
      </geometry>
    </collision>
    <inertial>
      <origin xyz="-0.0148797157 0.00826289929 -0.94794117" rpy="0 0 0" />
      <mass value="11.4094013" />
      <inertia ixx="-60.1743004" ixy="-1.60346989e-05" ixz="-1.34165492" iyy="-60.1957762" iyz="0.0831256208" izz="0.0279499556" />
    </inertial>
  </link>
  <link name="link_3">
    <visual>
      <origin xyz="0.0323570664 -0.0251250736 -1.51021693" rpy="0 0 0" />
      <geometry>
        <mesh filename="meshes/link_3.stl" />
      </geometry>
    </visual>
    <collision>
      <origin xyz="0.0323570664 -0.0251250736 -1.51021693" rpy="0 0 0" />
      <geometry>
        <mesh filename="meshes/link_3.stl" />
      </geometry>
    </collision>
    <inertial>
      <origin xyz="0.35880237 -0.0639950513 0.398196623" rpy="0 0 0" />
      <mass value="15.8262726" />
      <inertia ixx="1.32856102" ixy="0.204755507" ixz="-1.27760875" iyy="2.567548" iyz="0.200021063" izz="1.38279242" />
    </inertial>
  </link>
  <joint name="joint_1_2" type="revolute">
    <parent link="link_1" />
    <child link="link_2" />
    <origin xyz="0.0172239204 0.0133358395 0.0818112754" rpy="0 0 0" />
    <axis xyz="0.00848975594 0.999811721 -0.0174483992" />
    <limit lower="-1.57" upper="1.57" effort="10.0" velocity="1.0" />
  </joint>
  <joint name="joint_2_3" type="revolute">
    <parent link="link_2" />
    <child link="link_3" />
    <origin xyz="-0.0495809867 0.0117892341 1.42840565" rpy="0 0 0" />
    <axis xyz="0.0551568588 0.998477632 0.000373514033" />
    <limit lower="-1.57" upper="1.57" effort="10.0" velocity="1.0" />
  </joint>
  <joint name="base_to_1" type="fixed">
    <parent link="base" />
    <child link="link_1" />
    <origin xyz="0 0 0" rpy="0 0 0" />
  </joint>
</robot>