<?xml version='1.0' encoding='utf-8'?>
<robot name="object">
  <link name="base">
    <inertial>
      <origin xyz="0 0 0" rpy="0 0 0" />
      <mass value="0.0" />
      <inertia ixx="0" ixy="0" ixz="0" iyy="0" iyz="0" izz="0" />
    </inertial>
  </link>
  <link name="link_1">
    <visual>
      <origin xyz="0 0 0" rpy="0 0 0" />
      <geometry>
        <mesh filename="meshes/link_1.stl" />
      </geometry>
    </visual>
    <collision>
      <origin xyz="0 0 0" rpy="0 0 0" />
      <geometry>
        <mesh filename="meshes/link_1.stl" />
      </geometry>
    </collision>
    <inertial>
      <origin xyz="-0.128654223 0.00574132954 -0.649306765" rpy="0 0 0" />
      <mass value="78.0092556" />
      <inertia ixx="10.7105305" ixy="-0.0019015186" ixz="-4.27229297" iyy="13.7008788" iyz="-0.0105959508" izz="8.02366287" />
    </inertial>
  </link>
  <link name="link_2">
    <visual>
      <origin xyz="-0.159461204 -0.00893195752 -0.736343307" rpy="0 0 0" />
      <geometry>
        <mesh filename="meshes/link_2.stl" />
      </geometry>
    </visual>
    <collision>
      <origin xyz="-0.159461204 -0.00893195752 -0.736343307" rpy="0 0 0" />
      <geometry>
        <mesh filename="meshes/link_2.stl" />
      </geometry>
    </collision>
    <inertial>
      <origin xyz="-0.154459635 0.0148976228 -0.593632586" rpy="0 0 0" />
      <mass value="923.043367" />
      <inertia ixx="134.236633" ixy="0.0212454683" ixz="0.256286458" iyy="134.163694" iyz="0.0108528901" izz="134.907962" />
    </inertial>
  </link>
  <joint name="joint_1_2" type="revolute">
    <parent link="link_1" />
    <child link="link_2" />
    <origin xyz="0.159461204 0.00893195752 0.736343307" rpy="0 0 0" />
    <axis xyz="-0.271049574 -0.00396471424 -0.962557224" />
    <limit lower="-1.57" upper="1.57" effort="10.0" velocity="1.0" />
  </joint>
  <joint name="base_to_1" type="fixed">
    <parent link="base" />
    <child link="link_1" />
    <origin xyz="0 0 0" rpy="0 0 0" />
  </joint>
</robot>