<?xml version="1.0" ?>
<robot name="partnet_19654d8fe7090a887eaeab1f0c9120b7">
	<link name="base"/>
	<link name="link_0">
		<visual name="lamp_base_part-16">
			<origin xyz="0 0 0"/>
			<geometry>
				<mesh filename="textured_objs/original-29.obj"/>
			</geometry>
		</visual>
		<collision>
			<origin xyz="0 0 0"/>
			<geometry>
				<mesh filename="textured_objs/original-29.obj"/>
			</geometry>
		</collision>
	</link>
	<joint name="joint_0" type="fixed">
		<origin rpy="1.570796326794897 0 -1.570796326794897" xyz="0 0 0"/>
		<child link="link_0"/>
		<parent link="base"/>
	</joint>
	<link name="link_1">
		<visual name="lamp_shade-13">
			<origin xyz="0 -0.5613646043317658 -0.5857149599509234"/>
			<geometry>
				<mesh filename="textured_objs/new-0.obj"/>
			</geometry>
		</visual>
		<collision>
			<origin xyz="0 -0.5613646043317658 -0.5857149599509234"/>
			<geometry>
				<mesh filename="textured_objs/new-0.obj"/>
			</geometry>
		</collision>
	</link>
	<joint name="joint_1" type="revolute">
		<origin xyz="0.02155600000000002 0.1222978197879897 0.8947739375799466"/>
		<axis xyz="-1 0 0"/>
		<child link="link_1"/>
		<parent link="link_2"/>
		<limit lower="-0.3490658503988659" upper="1.5707963267948966"/>
	</joint>
	<link name="link_2">
		<visual name="lamp_arm_straight_bar-17">
			<origin xyz="0.02155600000000002 -0.4390667845437761 0.30905897762902323"/>
			<geometry>
				<mesh filename="textured_objs/original-32.obj"/>
			</geometry>
		</visual>
		<visual name="lamp_arm_straight_bar-17">
			<origin xyz="0.02155600000000002 -0.4390667845437761 0.30905897762902323"/>
			<geometry>
				<mesh filename="textured_objs/original-35.obj"/>
			</geometry>
		</visual>
		<visual name="lamp_arm_straight_bar-23">
			<origin xyz="0.02155600000000002 -0.4390667845437761 0.30905897762902323"/>
			<geometry>
				<mesh filename="textured_objs/original-26.obj"/>
			</geometry>
		</visual>
		<visual name="lamp_arm_straight_bar-23">
			<origin xyz="0.02155600000000002 -0.4390667845437761 0.30905897762902323"/>
			<geometry>
				<mesh filename="textured_objs/original-1.obj"/>
			</geometry>
		</visual>
		<visual name="lamp_arm_straight_bar-24">
			<origin xyz="0.02155600000000002 -0.4390667845437761 0.30905897762902323"/>
			<geometry>
				<mesh filename="textured_objs/original-25.obj"/>
			</geometry>
		</visual>
		<visual name="lamp_arm_straight_bar-24">
			<origin xyz="0.02155600000000002 -0.4390667845437761 0.30905897762902323"/>
			<geometry>
				<mesh filename="textured_objs/original-2.obj"/>
			</geometry>
		</visual>
		<collision>
			<origin xyz="0.02155600000000002 -0.4390667845437761 0.30905897762902323"/>
			<geometry>
				<mesh filename="textured_objs/original-32.obj"/>
			</geometry>
		</collision>
		<collision>
			<origin xyz="0.02155600000000002 -0.4390667845437761 0.30905897762902323"/>
			<geometry>
				<mesh filename="textured_objs/original-35.obj"/>
			</geometry>
		</collision>
		<collision>
			<origin xyz="0.02155600000000002 -0.4390667845437761 0.30905897762902323"/>
			<geometry>
				<mesh filename="textured_objs/original-26.obj"/>
			</geometry>
		</collision>
		<collision>
			<origin xyz="0.02155600000000002 -0.4390667845437761 0.30905897762902323"/>
			<geometry>
				<mesh filename="textured_objs/original-1.obj"/>
			</geometry>
		</collision>
		<collision>
			<origin xyz="0.02155600000000002 -0.4390667845437761 0.30905897762902323"/>
			<geometry>
				<mesh filename="textured_objs/original-25.obj"/>
			</geometry>
		</collision>
		<collision>
			<origin xyz="0.02155600000000002 -0.4390667845437761 0.30905897762902323"/>
			<geometry>
				<mesh filename="textured_objs/original-2.obj"/>
			</geometry>
		</collision>
	</link>
	<joint name="joint_2" type="revolute">
		<origin xyz="-0.013120328730106589 0.4390667845437761 0.37888020331136707"/>
		<axis xyz="-0.9999999999999999 0 0"/>
		<child link="link_2"/>
		<parent link="link_3"/>
		<limit lower="-0.08726646259971647" upper="0.08726646259971647"/>
	</joint>
	<link name="link_3">
		<visual name="lamp_joint-22">
			<origin xyz="0.008435671269893431 0 0.6879391809403903"/>
			<geometry>
				<mesh filename="textured_objs/original-6.obj"/>
			</geometry>
		</visual>
		<visual name="lamp_joint-22">
			<origin xyz="0.008435671269893431 0 0.6879391809403903"/>
			<geometry>
				<mesh filename="textured_objs/original-30.obj"/>
			</geometry>
		</visual>
		<visual name="lamp_joint-22">
			<origin xyz="0.008435671269893431 0 0.6879391809403903"/>
			<geometry>
				<mesh filename="textured_objs/original-31.obj"/>
			</geometry>
		</visual>
		<visual name="lamp_joint-22">
			<origin xyz="0.008435671269893431 0 0.6879391809403903"/>
			<geometry>
				<mesh filename="textured_objs/original-22.obj"/>
			</geometry>
		</visual>
		<visual name="lamp_joint-22">
			<origin xyz="0.008435671269893431 0 0.6879391809403903"/>
			<geometry>
				<mesh filename="textured_objs/original-21.obj"/>
			</geometry>
		</visual>
		<visual name="lamp_joint-22">
			<origin xyz="0.008435671269893431 0 0.6879391809403903"/>
			<geometry>
				<mesh filename="textured_objs/original-17.obj"/>
			</geometry>
		</visual>
		<visual name="lamp_joint-27">
			<origin xyz="0.008435671269893431 0 0.6879391809403903"/>
			<geometry>
				<mesh filename="textured_objs/original-37.obj"/>
			</geometry>
		</visual>
		<visual name="lamp_joint-27">
			<origin xyz="0.008435671269893431 0 0.6879391809403903"/>
			<geometry>
				<mesh filename="textured_objs/original-27.obj"/>
			</geometry>
		</visual>
		<visual name="lamp_arm_straight_bar-25">
			<origin xyz="0.008435671269893431 0 0.6879391809403903"/>
			<geometry>
				<mesh filename="textured_objs/original-23.obj"/>
			</geometry>
		</visual>
		<visual name="lamp_arm_straight_bar-25">
			<origin xyz="0.008435671269893431 0 0.6879391809403903"/>
			<geometry>
				<mesh filename="textured_objs/original-38.obj"/>
			</geometry>
		</visual>
		<visual name="lamp_arm_straight_bar-26">
			<origin xyz="0.008435671269893431 0 0.6879391809403903"/>
			<geometry>
				<mesh filename="textured_objs/original-24.obj"/>
			</geometry>
		</visual>
		<visual name="lamp_arm_straight_bar-26">
			<origin xyz="0.008435671269893431 0 0.6879391809403903"/>
			<geometry>
				<mesh filename="textured_objs/original-39.obj"/>
			</geometry>
		</visual>
		<collision>
			<origin xyz="0.008435671269893431 0 0.6879391809403903"/>
			<geometry>
				<mesh filename="textured_objs/original-6.obj"/>
			</geometry>
		</collision>
		<collision>
			<origin xyz="0.008435671269893431 0 0.6879391809403903"/>
			<geometry>
				<mesh filename="textured_objs/original-30.obj"/>
			</geometry>
		</collision>
		<collision>
			<origin xyz="0.008435671269893431 0 0.6879391809403903"/>
			<geometry>
				<mesh filename="textured_objs/original-31.obj"/>
			</geometry>
		</collision>
		<collision>
			<origin xyz="0.008435671269893431 0 0.6879391809403903"/>
			<geometry>
				<mesh filename="textured_objs/original-22.obj"/>
			</geometry>
		</collision>
		<collision>
			<origin xyz="0.008435671269893431 0 0.6879391809403903"/>
			<geometry>
				<mesh filename="textured_objs/original-21.obj"/>
			</geometry>
		</collision>
		<collision>
			<origin xyz="0.008435671269893431 0 0.6879391809403903"/>
			<geometry>
				<mesh filename="textured_objs/original-17.obj"/>
			</geometry>
		</collision>
		<collision>
			<origin xyz="0.008435671269893431 0 0.6879391809403903"/>
			<geometry>
				<mesh filename="textured_objs/original-37.obj"/>
			</geometry>
		</collision>
		<collision>
			<origin xyz="0.008435671269893431 0 0.6879391809403903"/>
			<geometry>
				<mesh filename="textured_objs/original-27.obj"/>
			</geometry>
		</collision>
		<collision>
			<origin xyz="0.008435671269893431 0 0.6879391809403903"/>
			<geometry>
				<mesh filename="textured_objs/original-23.obj"/>
			</geometry>
		</collision>
		<collision>
			<origin xyz="0.008435671269893431 0 0.6879391809403903"/>
			<geometry>
				<mesh filename="textured_objs/original-38.obj"/>
			</geometry>
		</collision>
		<collision>
			<origin xyz="0.008435671269893431 0 0.6879391809403903"/>
			<geometry>
				<mesh filename="textured_objs/original-24.obj"/>
			</geometry>
		</collision>
		<collision>
			<origin xyz="0.008435671269893431 0 0.6879391809403903"/>
			<geometry>
				<mesh filename="textured_objs/original-39.obj"/>
			</geometry>
		</collision>
	</link>
	<joint name="joint_3" type="revolute">
		<origin xyz="-0.008435671269893431 0 -0.6879391809403903"/>
		<axis xyz="0 1 0"/>
		<child link="link_3"/>
		<parent link="link_0"/>
		<limit lower="-1.0471975511965976" upper="1.0471975511965976"/>
	</joint>
</robot>
